Workbook

Sheet Instructions
A2: Controlled Mass Pollination Optimization using Excel solver
A4: Description and instruction for user
B5: Cells with gree colur are input values
B6: Cells with yellow color are output
A8: List of input data required
A9: 1. Estimated values of parental general combining ability (GCA) values in vector form with parental ID
A10: 2. Estimated values of parental specific combining ability (SCA) in two dimentional matrix
A11: 3. Estimated values of genomic relationship matrix (G) or Numerator pedigree based relationship matrix (A) in two dimentioal matrix form.
A13: The following intruxtions are for providing input data
A14: Step-1: Provide parental ID and their estimated general combing abiliy(GCA) values in B4:B33 of and C4:C33, respectively in sheet optimzation.
A16: Step-2: Provide SCA matrix in cells from F4:AI4 to F33:AI33. Make sure to paste parental IDs in cells F3:AI3.
A18: Step-3: Provide relationship matrix (G or A) in cells AT43:BW43 to AT72:BW72. Make use to provide parental IDs in cells rows AS43:A72 and column AT42:BW42.
A20: Step-4: Provide maximul limit of proportion of a parent being used as male parent in column AO4:AO33 and female parent in column AP4:AP33. Users may decide what proportion of parents to be used as male or female depending on their reproductive materials availability (pollen/strobili).
A21: Step-5: Provide deriable diversity contraints as status number Ns in cell AL37
A22: Step-6: Provide desirable number of controlled crossed in cell AV1
A24: The following instruction to run solver function
... A66: Note: We provide this optimization tool for 30 seed orchard parents, user may expand the rows and column of input data if the seed orchard parents are more than 30.
B69: For further details please contact:
B70: lstiburek@fld.czu.cz
B71: csagariya@gmail.com

Sheet Optimization
AT1: Number of crosses | AV1: 5000
F2: SCA | AL2: GCA | AO2: Upper M | AP2: Upper F
B3: ID | C3: GCA | D3: M | F3: 1 | G3: 2 | H3: 3 | I3: 4 | J3: 5 | K3: 6 | L3: 7 | M3: 8 | N3: 9 | O3: 10 | P3: 11 | Q3: 12 | R3: 13 | S3: 14 | T3: 15 | U3: 16 | V3: 17 | W3: 18 | X3: 19 | Y3: 20 | Z3: 21 | AA3: 22 | AB3: 23 | AC3: 24 | AD3: 25 | AE3: 26 | AF3: 27 | AG3: 28 | AH3: 29 | AI3: 30 | AK3: F | AL3: contrib | AM3: =SUM(AM4:AM33) -> 100 | AT3: 1 | AU3: 2 | AV3: 3 | AW3: 4 | AX3: 5 | AY3: 6 | AZ3: 7 | BA3: 8 | BB3: 9 | BC3: 10 | BD3: 11 | BE3: 12 | BF3: 13 | BG3: 14 | BH3: 15 | BI3: 16 | BJ3: 17 | BK3: 18 | BL3: 19 | BM3: 20 | BN3: 21 | BO3: 22 | BP3: 23 | BQ3: 24 | BR3: 25 | BS3: 26 | BT3: 27 | BU3: 28 | BV3: 29 | BW3: 30 | CG3: Parent-specific contribution
B4: 1 | C4: -0.11117586 | D4: 0 | F4: 0 | G4: 1.63653 | H4: 0.14443892 | I4: -0.13035389 | J4: 0.65183594 | K4: 0.10715813 | L4: -1.4849538 | M4: -0.055826057 | N4: 0.23310062 | O4: -0.55120302 | P4: -0.0083762498 | Q4: -1.5917527 | R4: 0.48265321 | S4: 0.42670492 | T4: 0.21735479 | U4: -0.74091372 | V4: 1.185531 | W4: 0.73219836 | X4: -1.3473814 | Y4: 0.54829275 | Z4: -0.48096576 | AA4: -0.27486141 | AB4: 0.40771738 | AC4: -1.0795591 | AD4: -0.39908677 | AE4: -0.29849895 | AF4: -0.1230612 | AG4: -0.10603838 | AH4: -1.3282765 | AI4: 1.231834 | AK4: 0 | AL4: =(AK4+D4)*C4 -> 0 | AM4: =100*(D4+AK4)/2 -> 0 | AO4: 0.2 | AP4: 0.2 | AQ4: =(D4+AK4)/2 -> 0 | AS4: 1 | AT4: {=ROUND(INDEX($D$4:$D$33,$AS4)*INDEX($AK$4:$AK$33,AT$3)*$AV$1,0)} -> 0 | AU4: {=ROUND(INDEX($D$4:$D$33,$AS4)*INDEX($AK$4:$AK$33,AU$3)*$AV$1,0)} -> 0 | AV4: {=ROUND(INDEX($D$4:$D$33,$AS4)*INDEX($AK$4:$AK$33,AV$3)*$AV$1,0)} -> 0 | AW4: {=ROUND(INDEX($D$4:$D$33,$AS4)*INDEX($AK$4:$AK$33,AW$3)*$AV$1,0)} -> 0 | AX4: {=ROUND(INDEX($D$4:$D$33,$AS4)*INDEX($AK$4:$AK$33,AX$3)*$AV$1,0)} -> 0 | AY4: {=ROUND(INDEX($D$4:$D$33,$AS4)*INDEX($AK$4:$AK$33,AY$3)*$AV$1,0)} -> 0 | AZ4: {=ROUND(INDEX($D$4:$D$33,$AS4)*INDEX($AK$4:$AK$33,AZ$3)*$AV$1,0)} -> 0 | BA4: {=ROUND(INDEX($D$4:$D$33,$AS4)*INDEX($AK$4:$AK$33,BA$3)*$AV$1,0)} -> 0 | ... BW4: {=ROUND(INDEX($D$4:$D$33,$AS4)*INDEX($AK$4:$AK$33,BW$3)*$AV$1,0)} -> 0 | BX4: =SUM(AT4:BW4) -> 0 | BZ4: =AT34+BX4 -> 0 | CA4: 1 | CD4: 0.021480473
B5: 2 | C5: -0.65676581 | D5: 0 | F5: 1.63653 | G5: 0 | H5: -0.82264505 | I5: 0.28425623 | J5: 0.11543159 | K5: 0.29080761 | L5: 0.87348695 | M5: 0.86840687 | N5: -0.74805022 | O5: -0.53243155 | P5: 0.55826105 | Q5: 0.25207588 | R5: -0.76817791 | S5: -0.56065515 | T5: 0.23868079 | U5: -0.51998537 | V5: 0.82943829 | W5: 0.74021599 | X5: -0.7613759 | Y5: 0.65205851 | Z5: -1.2483209 | AA5: 0.7272653 | AB5: 0.24017396 | AC5: 1.4303774 | AD5: 0.73773059 | AE5: -1.1837138 | AF5: 0.013568088 | AG5: 0.58846491 | AH5: -0.29981922 | AI5: -1.4152708 | AK5: 0 | AL5: =(AK5+D5)*C5 -> 0 | AM5: =100*(D5+AK5)/2 -> 0 | AO5: 0.2 | AP5: 0.2 | AQ5: =(D5+AK5)/2 -> 0 | AS5: 2 | AT5: {=ROUND(INDEX($D$4:$D$33,$AS5)*INDEX($AK$4:$AK$33,AT$3)*$AV$1,0)} -> 0 | AU5: {=ROUND(INDEX($D$4:$D$33,$AS5)*INDEX($AK$4:$AK$33,AU$3)*$AV$1,0)} -> 0 | AV5: {=ROUND(INDEX($D$4:$D$33,$AS5)*INDEX($AK$4:$AK$33,AV$3)*$AV$1,0)} -> 0 | AW5: {=ROUND(INDEX($D$4:$D$33,$AS5)*INDEX($AK$4:$AK$33,AW$3)*$AV$1,0)} -> 0 | AX5: {=ROUND(INDEX($D$4:$D$33,$AS5)*INDEX($AK$4:$AK$33,AX$3)*$AV$1,0)} -> 0 | AY5: {=ROUND(INDEX($D$4:$D$33,$AS5)*INDEX($AK$4:$AK$33,AY$3)*$AV$1,0)} -> 0 | AZ5: {=ROUND(INDEX($D$4:$D$33,$AS5)*INDEX($AK$4:$AK$33,AZ$3)*$AV$1,0)} -> 0 | BA5: {=ROUND(INDEX($D$4:$D$33,$AS5)*INDEX($AK$4:$AK$33,BA$3)*$AV$1,0)} -> 0 | ... BW5: {=ROUND(INDEX($D$4:$D$33,$AS5)*INDEX($AK$4:$AK$33,BW$3)*$AV$1,0)} -> 0 | BX5: =SUM(AT5:BW5) -> 0 | BZ5: =BX5+AU34 -> 0 | CA5: 2 | CD5: -0.77689396
B6: 3 | C6: 1.8797341 | D6: 0 | F6: 0.14443892 | G6: -0.82264505 | H6: 0 | I6: 0.38129195 | J6: -0.57605927 | K6: 0.049849463 | L6: 0.0018890549 | M6: -0.37573239 | N6: -0.4549307 | O6: -0.73053561 | P6: -0.9924825 | Q6: -0.60121156 | R6: 0.21035888 | S6: 0.65818776 | T6: 0.75447711 | U6: -0.95923461 | V6: -0.13368654 | W6: 0.47815306 | X6: 0.84495081 | Y6: 1.0921518 | Z6: -0.68134527 | AA6: -0.16950786 | AB6: -0.4757606 | AC6: 0.39053221 | AD6: 0.59821356 | AE6: -0.48622794 | AF6: -0.60813117 | AG6: 0.67040165 | AH6: 0.54959304 | AI6: 0.59078559 | AK6: 0 | AL6: =(AK6+D6)*C6 -> 0 | AM6: =100*(D6+AK6)/2 -> 0 | AO6: 0 | AP6: 0.2 | AQ6: =(D6+AK6)/2 -> 0 | AS6: 3 | AT6: {=ROUND(INDEX($D$4:$D$33,$AS6)*INDEX($AK$4:$AK$33,AT$3)*$AV$1,0)} -> 0 | AU6: {=ROUND(INDEX($D$4:$D$33,$AS6)*INDEX($AK$4:$AK$33,AU$3)*$AV$1,0)} -> 0 | AV6: {=ROUND(INDEX($D$4:$D$33,$AS6)*INDEX($AK$4:$AK$33,AV$3)*$AV$1,0)} -> 0 | AW6: {=ROUND(INDEX($D$4:$D$33,$AS6)*INDEX($AK$4:$AK$33,AW$3)*$AV$1,0)} -> 0 | AX6: {=ROUND(INDEX($D$4:$D$33,$AS6)*INDEX($AK$4:$AK$33,AX$3)*$AV$1,0)} -> 0 | AY6: {=ROUND(INDEX($D$4:$D$33,$AS6)*INDEX($AK$4:$AK$33,AY$3)*$AV$1,0)} -> 0 | AZ6: {=ROUND(INDEX($D$4:$D$33,$AS6)*INDEX($AK$4:$AK$33,AZ$3)*$AV$1,0)} -> 0 | BA6: {=ROUND(INDEX($D$4:$D$33,$AS6)*INDEX($AK$4:$AK$33,BA$3)*$AV$1,0)} -> 0 | ... BW6: {=ROUND(INDEX($D$4:$D$33,$AS6)*INDEX($AK$4:$AK$33,BW$3)*$AV$1,0)} -> 0 | BX6: =SUM(AT6:BW6) -> 0 | BZ6: =BX6+AV34 -> 0 | CA6: 3 | CD6: 0.8487205
B7: 4 | C7: -0.89608088 | D7: 0.015939244 | F7: -0.13035389 | G7: 0.28425623 | H7: 0.38129195 | I7: 0 | J7: 0.28546614 | K7: -1.3668562 | L7: -0.32494158 | M7: -0.20230664 | N7: 0.18274524 | O7: 0.82295811 | P7: 1.0904336 | Q7: -0.21181457 | R7: -0.10133424 | S7: -0.95486875 | T7: 0.23542521 | U7: 0.5151878 | V7: 0.061216103 | W7: 0.38650076 | X7: -0.20785295 | Y7: -0.71386832 | Z7: -0.45653122 | AA7: -0.31934552 | AB7: -0.37972602 | AC7: 1.287035 | AD7: -0.350397 | AE7: -0.72632977 | AF7: -0.016227706 | AG7: -1.3956432 | AH7: -0.50482192 | AI7: -0.24240916 | AK7: 0 | AL7: =(AK7+D7)*C7 -> -0.014282851 | AM7: =100*(D7+AK7)/2 -> 0.79696218 | AO7: 0.2 | AP7: 0.2 | AQ7: =(D7+AK7)/2 -> 0.0079696218 | AS7: 4 | AT7: {=ROUND(INDEX($D$4:$D$33,$AS7)*INDEX($AK$4:$AK$33,AT$3)*$AV$1,0)} -> 0 | AU7: {=ROUND(INDEX($D$4:$D$33,$AS7)*INDEX($AK$4:$AK$33,AU$3)*$AV$1,0)} -> 0 | AV7: {=ROUND(INDEX($D$4:$D$33,$AS7)*INDEX($AK$4:$AK$33,AV$3)*$AV$1,0)} -> 0 | AW7: {=ROUND(INDEX($D$4:$D$33,$AS7)*INDEX($AK$4:$AK$33,AW$3)*$AV$1,0)} -> 0 | AX7: {=ROUND(INDEX($D$4:$D$33,$AS7)*INDEX($AK$4:$AK$33,AX$3)*$AV$1,0)} -> 0 | AY7: {=ROUND(INDEX($D$4:$D$33,$AS7)*INDEX($AK$4:$AK$33,AY$3)*$AV$1,0)} -> 0 | AZ7: {=ROUND(INDEX($D$4:$D$33,$AS7)*INDEX($AK$4:$AK$33,AZ$3)*$AV$1,0)} -> 0 | BA7: {=ROUND(INDEX($D$4:$D$33,$AS7)*INDEX($AK$4:$AK$33,BA$3)*$AV$1,0)} -> 0 | ... BW7: {=ROUND(INDEX($D$4:$D$33,$AS7)*INDEX($AK$4:$AK$33,BW$3)*$AV$1,0)} -> 16 | BX7: =SUM(AT7:BW7) -> 80 | BZ7: =BX7+AW34 -> 80 | CA7: 4 | CD7: -1.4798982
B8: 5 | C8: 1.3315057 | D8: 0 | F8: 0.65183594 | G8: 0.11543159 | H8: -0.57605927 | I8: 0.28546614 | J8: 0 | K8: 0.57892389 | L8: -1.4871704 | M8: -0.1609415 | N8: 0.63052309 | O8: -0.41019693 | P8: -1.2550486 | Q8: -0.44848148 | R8: 0.98425987 | S8: 0.56553656 | T8: -0.051960788 | U8: 0.42934594 | V8: 1.0695415 | W8: 0.53032208 | X8: -0.026995789 | Y8: 0.60578289 | Z8: 0.31998546 | AA8: -0.69244649 | AB8: -0.7355026 | AC8: 0.24228624 | AD8: -0.14624221 | AE8: -0.34829075 | AF8: -0.42590262 | AG8: -0.27710005 | AH8: 1.1205095 | AI8: -0.33797024 | AK8: 0 | AL8: =(AK8+D8)*C8 -> 0 | AM8: =100*(D8+AK8)/2 -> 0 | AO8: 0.2 | AP8: 0.2 | AQ8: =(D8+AK8)/2 -> 0 | AS8: 5 | AT8: {=ROUND(INDEX($D$4:$D$33,$AS8)*INDEX($AK$4:$AK$33,AT$3)*$AV$1,0)} -> 0 | AU8: {=ROUND(INDEX($D$4:$D$33,$AS8)*INDEX($AK$4:$AK$33,AU$3)*$AV$1,0)} -> 0 | AV8: {=ROUND(INDEX($D$4:$D$33,$AS8)*INDEX($AK$4:$AK$33,AV$3)*$AV$1,0)} -> 0 | AW8: {=ROUND(INDEX($D$4:$D$33,$AS8)*INDEX($AK$4:$AK$33,AW$3)*$AV$1,0)} -> 0 | AX8: {=ROUND(INDEX($D$4:$D$33,$AS8)*INDEX($AK$4:$AK$33,AX$3)*$AV$1,0)} -> 0 | AY8: {=ROUND(INDEX($D$4:$D$33,$AS8)*INDEX($AK$4:$AK$33,AY$3)*$AV$1,0)} -> 0 | AZ8: {=ROUND(INDEX($D$4:$D$33,$AS8)*INDEX($AK$4:$AK$33,AZ$3)*$AV$1,0)} -> 0 | BA8: {=ROUND(INDEX($D$4:$D$33,$AS8)*INDEX($AK$4:$AK$33,BA$3)*$AV$1,0)} -> 0 | ... BW8: {=ROUND(INDEX($D$4:$D$33,$AS8)*INDEX($AK$4:$AK$33,BW$3)*$AV$1,0)} -> 0 | BX8: =SUM(AT8:BW8) -> 0 | BZ8: =BX8+AX34 -> 0 | CA8: 5 | CD8: 0.15084269
B9: 6 | C9: -0.62457313 | D9: 0 | F9: 0.10715813 | G9: 0.29080761 | H9: 0.049849463 | I9: -1.3668562 | J9: 0.57892389 | K9: 0 | L9: 0.26440256 | M9: 0.47695991 | N9: -0.59158138 | O9: 0.29507735 | P9: 0.14542113 | Q9: 1.148679 | R9: 0.21690315 | S9: 0.42400769 | T9: 0.74087596 | U9: -0.58568621 | V9: 1.2680339 | W9: -0.51607409 | X9: 0.6533204 | Y9: 0.23001232 | Z9: 0.43451586 | AA9: -0.80146826 | AB9: 0.70518651 | AC9: 0.12696914 | AD9: -0.11016452 | AE9: 0.24523051 | AF9: 0.61511345 | AG9: -0.4785071 | AH9: -0.62813096 | AI9: -0.62868964 | AK9: 0 | AL9: =(AK9+D9)*C9 -> 0 | AM9: =100*(D9+AK9)/2 -> 0 | AO9: 0.2 | AP9: 0.2 | AQ9: =(D9+AK9)/2 -> 0 | AS9: 6 | AT9: {=ROUND(INDEX($D$4:$D$33,$AS9)*INDEX($AK$4:$AK$33,AT$3)*$AV$1,0)} -> 0 | AU9: {=ROUND(INDEX($D$4:$D$33,$AS9)*INDEX($AK$4:$AK$33,AU$3)*$AV$1,0)} -> 0 | AV9: {=ROUND(INDEX($D$4:$D$33,$AS9)*INDEX($AK$4:$AK$33,AV$3)*$AV$1,0)} -> 0 | AW9: {=ROUND(INDEX($D$4:$D$33,$AS9)*INDEX($AK$4:$AK$33,AW$3)*$AV$1,0)} -> 0 | AX9: {=ROUND(INDEX($D$4:$D$33,$AS9)*INDEX($AK$4:$AK$33,AX$3)*$AV$1,0)} -> 0 | AY9: {=ROUND(INDEX($D$4:$D$33,$AS9)*INDEX($AK$4:$AK$33,AY$3)*$AV$1,0)} -> 0 | AZ9: {=ROUND(INDEX($D$4:$D$33,$AS9)*INDEX($AK$4:$AK$33,AZ$3)*$AV$1,0)} -> 0 | BA9: {=ROUND(INDEX($D$4:$D$33,$AS9)*INDEX($AK$4:$AK$33,BA$3)*$AV$1,0)} -> 0 | ... BW9: {=ROUND(INDEX($D$4:$D$33,$AS9)*INDEX($AK$4:$AK$33,BW$3)*$AV$1,0)} -> 0 | BX9: =SUM(AT9:BW9) -> 0 | BZ9: =BX9+AY34 -> 0 | CA9: 6 | CD9: 0.44424195
B10: 7 | C10: 0.77667888 | D10: 0.2 | F10: -1.4849538 | G10: 0.87348695 | H10: 0.0018890549 | I10: -0.32494158 | J10: -1.4871704 | K10: 0.26440256 | L10: 0 | M10: 0.7331566 | N10: 0.39113488 | O10: -1.1654004 | P10: -0.24480737 | Q10: 0.87756911 | R10: -0.37984659 | S10: 0.77812072 | T10: 1.4558359 | U10: 2.0418729 | V10: 0.77967046 | W10: 0.5891631 | X10: 1.5719416 | Y10: 0.88560794 | Z10: -0.55529142 | AA10: 0.015641833 | AB10: -0.018422924 | AC10: -0.72076685 | AD10: -0.19473585 | AE10: 0.58644076 | AF10: -0.40362536 | AG10: -0.01132855 | AH10: 1.5137951 | AI10: 0.8933793 | AK10: 0 | AL10: =(AK10+D10)*C10 -> 0.15533578 | AM10: =100*(D10+AK10)/2 -> 10 | AO10: 0.2 | AP10: 0.2 | AQ10: =(D10+AK10)/2 -> 0.1 | AS10: 7 | AT10: {=ROUND(INDEX($D$4:$D$33,$AS10)*INDEX($AK$4:$AK$33,AT$3)*$AV$1,0)} -> 0 | AU10: {=ROUND(INDEX($D$4:$D$33,$AS10)*INDEX($AK$4:$AK$33,AU$3)*$AV$1,0)} -> 0 | AV10: {=ROUND(INDEX($D$4:$D$33,$AS10)*INDEX($AK$4:$AK$33,AV$3)*$AV$1,0)} -> 0 | AW10: {=ROUND(INDEX($D$4:$D$33,$AS10)*INDEX($AK$4:$AK$33,AW$3)*$AV$1,0)} -> 0 | AX10: {=ROUND(INDEX($D$4:$D$33,$AS10)*INDEX($AK$4:$AK$33,AX$3)*$AV$1,0)} -> 0 | AY10: {=ROUND(INDEX($D$4:$D$33,$AS10)*INDEX($AK$4:$AK$33,AY$3)*$AV$1,0)} -> 0 | AZ10: {=ROUND(INDEX($D$4:$D$33,$AS10)*INDEX($AK$4:$AK$33,AZ$3)*$AV$1,0)} -> 0 | BA10: {=ROUND(INDEX($D$4:$D$33,$AS10)*INDEX($AK$4:$AK$33,BA$3)*$AV$1,0)} -> 0 | ... BW10: {=ROUND(INDEX($D$4:$D$33,$AS10)*INDEX($AK$4:$AK$33,BW$3)*$AV$1,0)} -> 200 | BX10: =SUM(AT10:BW10) -> 1000 | BZ10: =BX10+AZ34 -> 1000 | CA10: 7 | CD10: -0.016507078
B11: 8 | C11: -1.3242537 | D11: 0 | F11: -0.055826057 | G11: 0.86840687 | H11: -0.37573239 | I11: -0.20230664 | J11: -0.1609415 | K11: 0.47695991 | L11: 0.7331566 | M11: 0 | N11: 1.0312511 | O11: -0.4049427 | P11: -0.81952463 | Q11: 0.39264264 | R11: -0.16187954 | S11: -1.0039091 | T11: 0.018875049 | U11: 0.64992688 | V11: -0.23040895 | W11: -0.84750315 | X11: -0.92057907 | Y11: 0.15567563 | Z11: 0.585609 | AA11: 0.7355604 | AB11: -0.46456859 | AC11: 0.026586837 | AD11: -1.727638 | AE11: 0.11004884 | AF11: 0.92254772 | AG11: 0.36428359 | AH11: -0.48944384 | AI11: 0.27096414 | AK11: 0 | AL11: =(AK11+D11)*C11 -> 0 | AM11: =100*(D11+AK11)/2 -> 0 | AO11: 0.2 | AP11: 0.2 | AQ11: =(D11+AK11)/2 -> 0 | AS11: 8 | AT11: {=ROUND(INDEX($D$4:$D$33,$AS11)*INDEX($AK$4:$AK$33,AT$3)*$AV$1,0)} -> 0 | AU11: {=ROUND(INDEX($D$4:$D$33,$AS11)*INDEX($AK$4:$AK$33,AU$3)*$AV$1,0)} -> 0 | AV11: {=ROUND(INDEX($D$4:$D$33,$AS11)*INDEX($AK$4:$AK$33,AV$3)*$AV$1,0)} -> 0 | AW11: {=ROUND(INDEX($D$4:$D$33,$AS11)*INDEX($AK$4:$AK$33,AW$3)*$AV$1,0)} -> 0 | AX11: {=ROUND(INDEX($D$4:$D$33,$AS11)*INDEX($AK$4:$AK$33,AX$3)*$AV$1,0)} -> 0 | AY11: {=ROUND(INDEX($D$4:$D$33,$AS11)*INDEX($AK$4:$AK$33,AY$3)*$AV$1,0)} -> 0 | AZ11: {=ROUND(INDEX($D$4:$D$33,$AS11)*INDEX($AK$4:$AK$33,AZ$3)*$AV$1,0)} -> 0 | BA11: {=ROUND(INDEX($D$4:$D$33,$AS11)*INDEX($AK$4:$AK$33,BA$3)*$AV$1,0)} -> 0 | ... BW11: {=ROUND(INDEX($D$4:$D$33,$AS11)*INDEX($AK$4:$AK$33,BW$3)*$AV$1,0)} -> 0 | BX11: =SUM(AT11:BW11) -> 0 | BZ11: =BX11+BA34 -> 0 | CA11: 8 | CD11: 0.70231001
B12: 9 | C12: 1.5002767 | D12: 0 | F12: 0.23310062 | G12: -0.74805022 | H12: -0.4549307 | I12: 0.18274524 | J12: 0.63052309 | K12: -0.59158138 | L12: 0.39113488 | M12: 1.0312511 | N12: 0 | O12: 0.46614745 | P12: 0.23746508 | Q12: 0.49739137 | R12: -0.37916508 | S12: -0.14399246 | T12: -0.17007635 | U12: 0.28693618 | V12: -0.41211238 | W12: 0.43753892 | X12: -0.64275359 | Y12: 0.5764311 | Z12: 0.47193509 | AA12: 0.87079075 | AB12: 0.47923852 | AC12: 0.096960817 | AD12: -0.30216288 | AE12: 0.059194642 | AF12: -0.030154022 | AG12: 0.31454206 | AH12: 0.070213828 | AI12: -0.084051916 | AK12: 0.093570648 | AL12: =(AK12+D12)*C12 -> 0.14038186 | AM12: =100*(D12+AK12)/2 -> 4.6785324 | AO12: 0.2 | AP12: 0.2 | AQ12: =(D12+AK12)/2 -> 0.046785324 | AS12: 9 | AT12: {=ROUND(INDEX($D$4:$D$33,$AS12)*INDEX($AK$4:$AK$33,AT$3)*$AV$1,0)} -> 0 | AU12: {=ROUND(INDEX($D$4:$D$33,$AS12)*INDEX($AK$4:$AK$33,AU$3)*$AV$1,0)} -> 0 | AV12: {=ROUND(INDEX($D$4:$D$33,$AS12)*INDEX($AK$4:$AK$33,AV$3)*$AV$1,0)} -> 0 | AW12: {=ROUND(INDEX($D$4:$D$33,$AS12)*INDEX($AK$4:$AK$33,AW$3)*$AV$1,0)} -> 0 | AX12: {=ROUND(INDEX($D$4:$D$33,$AS12)*INDEX($AK$4:$AK$33,AX$3)*$AV$1,0)} -> 0 | AY12: {=ROUND(INDEX($D$4:$D$33,$AS12)*INDEX($AK$4:$AK$33,AY$3)*$AV$1,0)} -> 0 | AZ12: {=ROUND(INDEX($D$4:$D$33,$AS12)*INDEX($AK$4:$AK$33,AZ$3)*$AV$1,0)} -> 0 | BA12: {=ROUND(INDEX($D$4:$D$33,$AS12)*INDEX($AK$4:$AK$33,BA$3)*$AV$1,0)} -> 0 | ... BW12: {=ROUND(INDEX($D$4:$D$33,$AS12)*INDEX($AK$4:$AK$33,BW$3)*$AV$1,0)} -> 0 | BX12: =SUM(AT12:BW12) -> 0 | BZ12: =BX12+BB34 -> 469 | CA12: 9 | CD12: 1.4631252
B13: 10 | C13: -2.2029029 | D13: 0 | F13: -0.55120302 | G13: -0.53243155 | H13: -0.73053561 | I13: 0.82295811 | J13: -0.41019693 | K13: 0.29507735 | L13: -1.1654004 | M13: -0.4049427 | N13: 0.46614745 | O13: 0 | P13: 0.23493132 | Q13: 0.3239704 | R13: 1.0175417 | S13: 0.012666451 | T13: 0.73431284 | U13: 1.3549466 | V13: 0.53145243 | W13: -0.58860462 | X13: -0.054800895 | Y13: 0.80569316 | Z13: -0.088742526 | AA13: 0.39610667 | AB13: -0.36121428 | AC13: -1.0755464 | AD13: 0.2185387 | AE13: 0.26489408 | AF13: 0.63323588 | AG13: 0.80673694 | AH13: 1.014683 | AI13: 0.2950383 | AK13: 0 | AL13: =(AK13+D13)*C13 -> 0 | AM13: =100*(D13+AK13)/2 -> 0 | AO13: 0.2 | AP13: 0.2 | AQ13: =(D13+AK13)/2 -> 0 | AS13: 10 | AT13: {=ROUND(INDEX($D$4:$D$33,$AS13)*INDEX($AK$4:$AK$33,AT$3)*$AV$1,0)} -> 0 | AU13: {=ROUND(INDEX($D$4:$D$33,$AS13)*INDEX($AK$4:$AK$33,AU$3)*$AV$1,0)} -> 0 | AV13: {=ROUND(INDEX($D$4:$D$33,$AS13)*INDEX($AK$4:$AK$33,AV$3)*$AV$1,0)} -> 0 | AW13: {=ROUND(INDEX($D$4:$D$33,$AS13)*INDEX($AK$4:$AK$33,AW$3)*$AV$1,0)} -> 0 | AX13: {=ROUND(INDEX($D$4:$D$33,$AS13)*INDEX($AK$4:$AK$33,AX$3)*$AV$1,0)} -> 0 | AY13: {=ROUND(INDEX($D$4:$D$33,$AS13)*INDEX($AK$4:$AK$33,AY$3)*$AV$1,0)} -> 0 | AZ13: {=ROUND(INDEX($D$4:$D$33,$AS13)*INDEX($AK$4:$AK$33,AZ$3)*$AV$1,0)} -> 0 | BA13: {=ROUND(INDEX($D$4:$D$33,$AS13)*INDEX($AK$4:$AK$33,BA$3)*$AV$1,0)} -> 0 | ... BW13: {=ROUND(INDEX($D$4:$D$33,$AS13)*INDEX($AK$4:$AK$33,BW$3)*$AV$1,0)} -> 0 | BX13: =SUM(AT13:BW13) -> 0 | BZ13: =BX13+BC34 -> 0 | CA13: 10 | CD13: 0.63496902
B14: 11 | C14: 0.3225147 | D14: 0 | F14: -0.0083762498 | G14: 0.55826105 | H14: -0.9924825 | I14: 1.0904336 | J14: -1.2550486 | K14: 0.14542113 | L14: -0.24480737 | M14: -0.81952463 | N14: 0.23746508 | O14: 0.23493132 | P14: 0 | Q14: 0.48364972 | R14: -0.36140206 | S14: 0.070959183 | T14: -0.35866244 | U14: -1.7364333 | V14: -0.61075239 | W14: -0.68624346 | X14: 0.00036094076 | Y14: -0.29112361 | Z14: -0.67262039 | AA14: -0.21852334 | AB14: 0.3153729 | AC14: -0.013377367 | AD14: 1.7335255 | AE14: 1.8760972 | AF14: 1.6156372 | AG14: 0.31655828 | AH14: 0.87214633 | AI14: 0.71645601 | AK14: 0.18307564 | AL14: =(AK14+D14)*C14 -> 0.059044585 | AM14: =100*(D14+AK14)/2 -> 9.1537819 | AO14: 0.2 | AP14: 0.2 | AQ14: =(D14+AK14)/2 -> 0.091537819 | AS14: 11 | AT14: {=ROUND(INDEX($D$4:$D$33,$AS14)*INDEX($AK$4:$AK$33,AT$3)*$AV$1,0)} -> 0 | AU14: {=ROUND(INDEX($D$4:$D$33,$AS14)*INDEX($AK$4:$AK$33,AU$3)*$AV$1,0)} -> 0 | AV14: {=ROUND(INDEX($D$4:$D$33,$AS14)*INDEX($AK$4:$AK$33,AV$3)*$AV$1,0)} -> 0 | AW14: {=ROUND(INDEX($D$4:$D$33,$AS14)*INDEX($AK$4:$AK$33,AW$3)*$AV$1,0)} -> 0 | AX14: {=ROUND(INDEX($D$4:$D$33,$AS14)*INDEX($AK$4:$AK$33,AX$3)*$AV$1,0)} -> 0 | AY14: {=ROUND(INDEX($D$4:$D$33,$AS14)*INDEX($AK$4:$AK$33,AY$3)*$AV$1,0)} -> 0 | AZ14: {=ROUND(INDEX($D$4:$D$33,$AS14)*INDEX($AK$4:$AK$33,AZ$3)*$AV$1,0)} -> 0 | BA14: {=ROUND(INDEX($D$4:$D$33,$AS14)*INDEX($AK$4:$AK$33,BA$3)*$AV$1,0)} -> 0 | ... BW14: {=ROUND(INDEX($D$4:$D$33,$AS14)*INDEX($AK$4:$AK$33,BW$3)*$AV$1,0)} -> 0 | BX14: =SUM(AT14:BW14) -> 0 | BZ14: =BX14+BD34 -> 916 | CA14: 11 | CD14: -0.20707581
B15: 12 | C15: 0.42100445 | D15: 0 | F15: -1.5917527 | G15: 0.25207588 | H15: -0.60121156 | I15: -0.21181457 | J15: -0.44848148 | K15: 1.148679 | L15: 0.87756911 | M15: 0.39264264 | N15: 0.49739137 | O15: 0.3239704 | P15: 0.48364972 | Q15: 0 | R15: -1.1362042 | S15: 0.6196777 | T15: -1.0486957 | U15: -0.064391555 | V15: -0.75722338 | W15: -0.32068056 | X15: 0.075558208 | Y15: -0.32602226 | Z15: 0.63076753 | AA15: -0.25993534 | AB15: 1.0724226 | AC15: 0.11543283 | AD15: -1.0342342 | AE15: 0.2352643 | AF15: 0.047254095 | AG15: 0.22304994 | AH15: -0.53573559 | AI15: -0.61484171 | AK15: 0.060602862 | AL15: =(AK15+D15)*C15 -> 0.025514074 | AM15: =100*(D15+AK15)/2 -> 3.0301431 | AO15: 0.2 | AP15: 0.2 | AQ15: =(D15+AK15)/2 -> 0.030301431 | AS15: 12 | AT15: {=ROUND(INDEX($D$4:$D$33,$AS15)*INDEX($AK$4:$AK$33,AT$3)*$AV$1,0)} -> 0 | AU15: {=ROUND(INDEX($D$4:$D$33,$AS15)*INDEX($AK$4:$AK$33,AU$3)*$AV$1,0)} -> 0 | AV15: {=ROUND(INDEX($D$4:$D$33,$AS15)*INDEX($AK$4:$AK$33,AV$3)*$AV$1,0)} -> 0 | AW15: {=ROUND(INDEX($D$4:$D$33,$AS15)*INDEX($AK$4:$AK$33,AW$3)*$AV$1,0)} -> 0 | AX15: {=ROUND(INDEX($D$4:$D$33,$AS15)*INDEX($AK$4:$AK$33,AX$3)*$AV$1,0)} -> 0 | AY15: {=ROUND(INDEX($D$4:$D$33,$AS15)*INDEX($AK$4:$AK$33,AY$3)*$AV$1,0)} -> 0 | AZ15: {=ROUND(INDEX($D$4:$D$33,$AS15)*INDEX($AK$4:$AK$33,AZ$3)*$AV$1,0)} -> 0 | BA15: {=ROUND(INDEX($D$4:$D$33,$AS15)*INDEX($AK$4:$AK$33,BA$3)*$AV$1,0)} -> 0 | ... BW15: {=ROUND(INDEX($D$4:$D$33,$AS15)*INDEX($AK$4:$AK$33,BW$3)*$AV$1,0)} -> 0 | BX15: =SUM(AT15:BW15) -> 0 | BZ15: =BX15+BE34 -> 304 | CA15: 12 | CD15: -0.61269409
B16: 13 | C16: -0.82070114 | D16: 0 | F16: 0.48265321 | G16: -0.76817791 | H16: 0.21035888 | I16: -0.10133424 | J16: 0.98425987 | K16: 0.21690315 | L16: -0.37984659 | M16: -0.16187954 | N16: -0.37916508 | O16: 1.0175417 | P16: -0.36140206 | Q16: -1.1362042 | R16: 0 | S16: 0.49546563 | T16: -0.075298325 | U16: -0.017451428 | V16: -0.25119035 | W16: -0.92115331 | X16: -0.22094579 | Y16: -0.93977929 | Z16: -0.091727009 | AA16: 0.25854183 | AB16: 0.66309382 | AC16: -0.50993054 | AD16: -0.44939574 | AE16: 0.099540007 | AF16: 1.0568343 | AG16: 0.66863418 | AH16: 0.52225361 | AI16: -0.56192395 | AK16: 0 | AL16: =(AK16+D16)*C16 -> 0 | AM16: =100*(D16+AK16)/2 -> 0 | AO16: 0.2 | AP16: 0.2 | AQ16: =(D16+AK16)/2 -> 0 | AS16: 13 | AT16: {=ROUND(INDEX($D$4:$D$33,$AS16)*INDEX($AK$4:$AK$33,AT$3)*$AV$1,0)} -> 0 | AU16: {=ROUND(INDEX($D$4:$D$33,$AS16)*INDEX($AK$4:$AK$33,AU$3)*$AV$1,0)} -> 0 | AV16: {=ROUND(INDEX($D$4:$D$33,$AS16)*INDEX($AK$4:$AK$33,AV$3)*$AV$1,0)} -> 0 | AW16: {=ROUND(INDEX($D$4:$D$33,$AS16)*INDEX($AK$4:$AK$33,AW$3)*$AV$1,0)} -> 0 | AX16: {=ROUND(INDEX($D$4:$D$33,$AS16)*INDEX($AK$4:$AK$33,AX$3)*$AV$1,0)} -> 0 | AY16: {=ROUND(INDEX($D$4:$D$33,$AS16)*INDEX($AK$4:$AK$33,AY$3)*$AV$1,0)} -> 0 | AZ16: {=ROUND(INDEX($D$4:$D$33,$AS16)*INDEX($AK$4:$AK$33,AZ$3)*$AV$1,0)} -> 0 | BA16: {=ROUND(INDEX($D$4:$D$33,$AS16)*INDEX($AK$4:$AK$33,BA$3)*$AV$1,0)} -> 0 | ... BW16: {=ROUND(INDEX($D$4:$D$33,$AS16)*INDEX($AK$4:$AK$33,BW$3)*$AV$1,0)} -> 0 | BX16: =SUM(AT16:BW16) -> 0 | BZ16: =BX16+BF34 -> 0 | CA16: 13 | CD16: 0.64786087
B17: 14 | C17: -0.96645875 | D17: 0 | F17: 0.42670492 | G17: -0.56065515 | H17: 0.65818776 | I17: -0.95486875 | J17: 0.56553656 | K17: 0.42400769 | L17: 0.77812072 | M17: -1.0039091 | N17: -0.14399246 | O17: 0.012666451 | P17: 0.070959183 | Q17: 0.6196777 | R17: 0.49546563 | S17: 0 | T17: 0.17342779 | U17: 0.14137613 | V17: 0.67590893 | W17: 0.011295888 | X17: 0.86242044 | Y17: -0.061871972 | Z17: -0.71664221 | AA17: 0.66286926 | AB17: -0.11325212 | AC17: 0.29034042 | AD17: -0.27257047 | AE17: 1.1156978 | AF17: -0.75834674 | AG17: 0.30311059 | AH17: -0.78797239 | AI17: 0.48684463 | AK17: 0 | AL17: =(AK17+D17)*C17 -> 0 | AM17: =100*(D17+AK17)/2 -> 0 | AO17: 0.2 | AP17: 0.2 | AQ17: =(D17+AK17)/2 -> 0 | AS17: 14 | AT17: {=ROUND(INDEX($D$4:$D$33,$AS17)*INDEX($AK$4:$AK$33,AT$3)*$AV$1,0)} -> 0 | AU17: {=ROUND(INDEX($D$4:$D$33,$AS17)*INDEX($AK$4:$AK$33,AU$3)*$AV$1,0)} -> 0 | AV17: {=ROUND(INDEX($D$4:$D$33,$AS17)*INDEX($AK$4:$AK$33,AV$3)*$AV$1,0)} -> 0 | AW17: {=ROUND(INDEX($D$4:$D$33,$AS17)*INDEX($AK$4:$AK$33,AW$3)*$AV$1,0)} -> 0 | AX17: {=ROUND(INDEX($D$4:$D$33,$AS17)*INDEX($AK$4:$AK$33,AX$3)*$AV$1,0)} -> 0 | AY17: {=ROUND(INDEX($D$4:$D$33,$AS17)*INDEX($AK$4:$AK$33,AY$3)*$AV$1,0)} -> 0 | AZ17: {=ROUND(INDEX($D$4:$D$33,$AS17)*INDEX($AK$4:$AK$33,AZ$3)*$AV$1,0)} -> 0 | BA17: {=ROUND(INDEX($D$4:$D$33,$AS17)*INDEX($AK$4:$AK$33,BA$3)*$AV$1,0)} -> 0 | ... BW17: {=ROUND(INDEX($D$4:$D$33,$AS17)*INDEX($AK$4:$AK$33,BW$3)*$AV$1,0)} -> 0 | BX17: =SUM(AT17:BW17) -> 0 | BZ17: =BX17+BG34 -> 0 | CA17: 14 | CD17: -1.7737961
B18: 15 | C18: 0.6093482 | D18: 0 | F18: 0.21735479 | G18: 0.23868079 | H18: 0.75447711 | I18: 0.23542521 | J18: -0.051960788 | K18: 0.74087596 | L18: 1.4558359 | M18: 0.018875049 | N18: -0.17007635 | O18: 0.73431284 | P18: -0.35866244 | Q18: -1.0486957 | R18: -0.075298325 | S18: 0.17342779 | T18: 0 | U18: -0.73419934 | V18: 0.11262914 | W18: 0.78535464 | X18: -0.64315703 | Y18: 0.25133827 | Z18: 0.17839386 | AA18: 0.68889433 | AB18: -0.080495707 | AC18: -0.85745967 | AD18: -0.66629085 | AE18: 0.063319815 | AF18: 1.2892994 | AG18: -0.93663854 | AH18: -1.2062316 | AI18: 1.1212401 | AK18: 0.19514524 | AL18: =(AK18+D18)*C18 -> 0.1189114 | AM18: =100*(D18+AK18)/2 -> 9.7572621 | AO18: 0.2 | AP18: 0.2 | AQ18: =(D18+AK18)/2 -> 0.097572621 | AS18: 15 | AT18: {=ROUND(INDEX($D$4:$D$33,$AS18)*INDEX($AK$4:$AK$33,AT$3)*$AV$1,0)} -> 0 | AU18: {=ROUND(INDEX($D$4:$D$33,$AS18)*INDEX($AK$4:$AK$33,AU$3)*$AV$1,0)} -> 0 | AV18: {=ROUND(INDEX($D$4:$D$33,$AS18)*INDEX($AK$4:$AK$33,AV$3)*$AV$1,0)} -> 0 | AW18: {=ROUND(INDEX($D$4:$D$33,$AS18)*INDEX($AK$4:$AK$33,AW$3)*$AV$1,0)} -> 0 | AX18: {=ROUND(INDEX($D$4:$D$33,$AS18)*INDEX($AK$4:$AK$33,AX$3)*$AV$1,0)} -> 0 | AY18: {=ROUND(INDEX($D$4:$D$33,$AS18)*INDEX($AK$4:$AK$33,AY$3)*$AV$1,0)} -> 0 | AZ18: {=ROUND(INDEX($D$4:$D$33,$AS18)*INDEX($AK$4:$AK$33,AZ$3)*$AV$1,0)} -> 0 | BA18: {=ROUND(INDEX($D$4:$D$33,$AS18)*INDEX($AK$4:$AK$33,BA$3)*$AV$1,0)} -> 0 | ... BW18: {=ROUND(INDEX($D$4:$D$33,$AS18)*INDEX($AK$4:$AK$33,BW$3)*$AV$1,0)} -> 0 | BX18: =SUM(AT18:BW18) -> 0 | BZ18: =BX18+BH34 -> 976 | CA18: 15 | CD18: 0.0031494589
B19: 16 | C19: -1.0362114 | D19: 0 | F19: -0.74091372 | G19: -0.51998537 | H19: -0.95923461 | I19: 0.5151878 | J19: 0.42934594 | K19: -0.58568621 | L19: 2.0418729 | M19: 0.64992688 | N19: 0.28693618 | O19: 1.3549466 | P19: -1.7364333 | Q19: -0.064391555 | R19: -0.017451428 | S19: 0.14137613 | T19: -0.73419934 | U19: 0 | V19: 0.17320001 | W19: -0.17633397 | X19: 0.14423326 | Y19: -0.52547843 | Z19: 0.37023073 | AA19: -1.4983055 | AB19: 1.369755 | AC19: -0.40569876 | AD19: -0.47642953 | AE19: -0.47587136 | AF19: -0.85448845 | AG19: 0.077655542 | AH19: 0.46751238 | AI19: 0.88400994 | AK19: 0 | AL19: =(AK19+D19)*C19 -> 0 | AM19: =100*(D19+AK19)/2 -> 0 | AO19: 0.2 | AP19: 0.2 | AQ19: =(D19+AK19)/2 -> 0 | AS19: 16 | AT19: {=ROUND(INDEX($D$4:$D$33,$AS19)*INDEX($AK$4:$AK$33,AT$3)*$AV$1,0)} -> 0 | AU19: {=ROUND(INDEX($D$4:$D$33,$AS19)*INDEX($AK$4:$AK$33,AU$3)*$AV$1,0)} -> 0 | AV19: {=ROUND(INDEX($D$4:$D$33,$AS19)*INDEX($AK$4:$AK$33,AV$3)*$AV$1,0)} -> 0 | AW19: {=ROUND(INDEX($D$4:$D$33,$AS19)*INDEX($AK$4:$AK$33,AW$3)*$AV$1,0)} -> 0 | AX19: {=ROUND(INDEX($D$4:$D$33,$AS19)*INDEX($AK$4:$AK$33,AX$3)*$AV$1,0)} -> 0 | AY19: {=ROUND(INDEX($D$4:$D$33,$AS19)*INDEX($AK$4:$AK$33,AY$3)*$AV$1,0)} -> 0 | AZ19: {=ROUND(INDEX($D$4:$D$33,$AS19)*INDEX($AK$4:$AK$33,AZ$3)*$AV$1,0)} -> 0 | BA19: {=ROUND(INDEX($D$4:$D$33,$AS19)*INDEX($AK$4:$AK$33,BA$3)*$AV$1,0)} -> 0 | ... BW19: {=ROUND(INDEX($D$4:$D$33,$AS19)*INDEX($AK$4:$AK$33,BW$3)*$AV$1,0)} -> 0 | BX19: =SUM(AT19:BW19) -> 0 | BZ19: =BX19+BI34 -> 0 | CA19: 16 | CD19: 0.16044818
B20: 17 | C20: -0.028237518 | D20: 0 | F20: 1.185531 | G20: 0.82943829 | H20: -0.13368654 | I20: 0.061216103 | J20: 1.0695415 | K20: 1.2680339 | L20: 0.77967046 | M20: -0.23040895 | N20: -0.41211238 | O20: 0.53145243 | P20: -0.61075239 | Q20: -0.75722338 | R20: -0.25119035 | S20: 0.67590893 | T20: 0.11262914 | U20: 0.17320001 | V20: 0 | W20: 0.35051399 | X20: 0.69985713 | Y20: 0.050933385 | Z20: -1.0335282 | AA20: -0.032855534 | AB20: -0.12077299 | AC20: 0.074523534 | AD20: -1.3606459 | AE20: 0.65894818 | AF20: -0.046238841 | AG20: -1.1700651 | AH20: -1.2230416 | AI20: -0.081744024 | AK20: 0.030265815 | AL20: =(AK20+D20)*C20 -> -0.00085463151 | AM20: =100*(D20+AK20)/2 -> 1.5132908 | AO20: 0.2 | AP20: 0.2 | AQ20: =(D20+AK20)/2 -> 0.015132908 | AS20: 17 | AT20: {=ROUND(INDEX($D$4:$D$33,$AS20)*INDEX($AK$4:$AK$33,AT$3)*$AV$1,0)} -> 0 | AU20: {=ROUND(INDEX($D$4:$D$33,$AS20)*INDEX($AK$4:$AK$33,AU$3)*$AV$1,0)} -> 0 | AV20: {=ROUND(INDEX($D$4:$D$33,$AS20)*INDEX($AK$4:$AK$33,AV$3)*$AV$1,0)} -> 0 | AW20: {=ROUND(INDEX($D$4:$D$33,$AS20)*INDEX($AK$4:$AK$33,AW$3)*$AV$1,0)} -> 0 | AX20: {=ROUND(INDEX($D$4:$D$33,$AS20)*INDEX($AK$4:$AK$33,AX$3)*$AV$1,0)} -> 0 | AY20: {=ROUND(INDEX($D$4:$D$33,$AS20)*INDEX($AK$4:$AK$33,AY$3)*$AV$1,0)} -> 0 | AZ20: {=ROUND(INDEX($D$4:$D$33,$AS20)*INDEX($AK$4:$AK$33,AZ$3)*$AV$1,0)} -> 0 | BA20: {=ROUND(INDEX($D$4:$D$33,$AS20)*INDEX($AK$4:$AK$33,BA$3)*$AV$1,0)} -> 0 | ... BW20: {=ROUND(INDEX($D$4:$D$33,$AS20)*INDEX($AK$4:$AK$33,BW$3)*$AV$1,0)} -> 0 | BX20: =SUM(AT20:BW20) -> 0 | BZ20: =BX20+BJ34 -> 149 | CA20: 17 | CD20: -1.1057766
B21: 18 | C21: -2.8197668 | D21: 0 | F21: 0.73219836 | G21: 0.74021599 | H21: 0.47815306 | I21: 0.38650076 | J21: 0.53032208 | K21: -0.51607409 | L21: 0.5891631 | M21: -0.84750315 | N21: 0.43753892 | O21: -0.58860462 | P21: -0.68624346 | Q21: -0.32068056 | R21: -0.92115331 | S21: 0.011295888 | T21: 0.78535464 | U21: -0.17633397 | V21: 0.35051399 | W21: 0 | X21: 0.26530616 | Y21: -0.25201523 | Z21: 1.3197481 | AA21: -0.68361733 | AB21: 0.21295831 | AC21: -0.42786752 | AD21: -0.079491271 | AE21: -0.25306673 | AF21: -0.23110818 | AG21: 0.78536382 | AH21: -1.5118463 | AI21: -0.94170341 | AK21: 0 | AL21: =(AK21+D21)*C21 -> 0 | AM21: =100*(D21+AK21)/2 -> 0 | AO21: 0.2 | AP21: 0.2 | AQ21: =(D21+AK21)/2 -> 0 | AS21: 18 | AT21: {=ROUND(INDEX($D$4:$D$33,$AS21)*INDEX($AK$4:$AK$33,AT$3)*$AV$1,0)} -> 0 | AU21: {=ROUND(INDEX($D$4:$D$33,$AS21)*INDEX($AK$4:$AK$33,AU$3)*$AV$1,0)} -> 0 | AV21: {=ROUND(INDEX($D$4:$D$33,$AS21)*INDEX($AK$4:$AK$33,AV$3)*$AV$1,0)} -> 0 | AW21: {=ROUND(INDEX($D$4:$D$33,$AS21)*INDEX($AK$4:$AK$33,AW$3)*$AV$1,0)} -> 0 | AX21: {=ROUND(INDEX($D$4:$D$33,$AS21)*INDEX($AK$4:$AK$33,AX$3)*$AV$1,0)} -> 0 | AY21: {=ROUND(INDEX($D$4:$D$33,$AS21)*INDEX($AK$4:$AK$33,AY$3)*$AV$1,0)} -> 0 | AZ21: {=ROUND(INDEX($D$4:$D$33,$AS21)*INDEX($AK$4:$AK$33,AZ$3)*$AV$1,0)} -> 0 | BA21: {=ROUND(INDEX($D$4:$D$33,$AS21)*INDEX($AK$4:$AK$33,BA$3)*$AV$1,0)} -> 0 | ... BW21: {=ROUND(INDEX($D$4:$D$33,$AS21)*INDEX($AK$4:$AK$33,BW$3)*$AV$1,0)} -> 0 | BX21: =SUM(AT21:BW21) -> 0 | BZ21: =BX21+BK34 -> 0 | CA21: 18 | CD21: 0.99290623
B22: 19 | C22: -2.0810495 | D22: 0 | F22: -1.3473814 | G22: -0.7613759 | H22: 0.84495081 | I22: -0.20785295 | J22: -0.026995789 | K22: 0.6533204 | L22: 1.5719416 | M22: -0.92057907 | N22: -0.64275359 | O22: -0.054800895 | P22: 0.00036094076 | Q22: 0.075558208 | R22: -0.22094579 | S22: 0.86242044 | T22: -0.64315703 | U22: 0.14423326 | V22: 0.69985713 | W22: 0.26530616 | X22: 0 | Y22: -0.30525219 | Z22: -1.5196093 | AA22: -0.33322338 | AB22: 0.23050881 | AC22: 0.29825384 | AD22: -0.36664155 | AE22: 0.14290745 | AF22: -0.81257225 | AG22: -1.4904833 | AH22: -0.042460111 | AI22: -1.6566137 | AK22: 0 | AL22: =(AK22+D22)*C22 -> 0 | AM22: =100*(D22+AK22)/2 -> 0 | AO22: 0.2 | AP22: 0.2 | AQ22: =(D22+AK22)/2 -> 0 | AS22: 19 | AT22: {=ROUND(INDEX($D$4:$D$33,$AS22)*INDEX($AK$4:$AK$33,AT$3)*$AV$1,0)} -> 0 | AU22: {=ROUND(INDEX($D$4:$D$33,$AS22)*INDEX($AK$4:$AK$33,AU$3)*$AV$1,0)} -> 0 | AV22: {=ROUND(INDEX($D$4:$D$33,$AS22)*INDEX($AK$4:$AK$33,AV$3)*$AV$1,0)} -> 0 | AW22: {=ROUND(INDEX($D$4:$D$33,$AS22)*INDEX($AK$4:$AK$33,AW$3)*$AV$1,0)} -> 0 | AX22: {=ROUND(INDEX($D$4:$D$33,$AS22)*INDEX($AK$4:$AK$33,AX$3)*$AV$1,0)} -> 0 | AY22: {=ROUND(INDEX($D$4:$D$33,$AS22)*INDEX($AK$4:$AK$33,AY$3)*$AV$1,0)} -> 0 | AZ22: {=ROUND(INDEX($D$4:$D$33,$AS22)*INDEX($AK$4:$AK$33,AZ$3)*$AV$1,0)} -> 0 | BA22: {=ROUND(INDEX($D$4:$D$33,$AS22)*INDEX($AK$4:$AK$33,BA$3)*$AV$1,0)} -> 0 | ... BW22: {=ROUND(INDEX($D$4:$D$33,$AS22)*INDEX($AK$4:$AK$33,BW$3)*$AV$1,0)} -> 0 | BX22: =SUM(AT22:BW22) -> 0 | BZ22: =BX22+BL34 -> 0 | CA22: 19 | CD22: 0.56811253
B23: 20 | C23: -0.044753129 | D23: 0 | F23: 0.54829275 | G23: 0.65205851 | H23: 1.0921518 | I23: -0.71386832 | J23: 0.60578289 | K23: 0.23001232 | L23: 0.88560794 | M23: 0.15567563 | N23: 0.5764311 | O23: 0.80569316 | P23: -0.29112361 | Q23: -0.32602226 | R23: -0.93977929 | S23: -0.061871972 | T23: 0.25133827 | U23: -0.52547843 | V23: 0.050933385 | W23: -0.25201523 | X23: -0.30525219 | Y23: 0 | Z23: -1.1562869 | AA23: 1.2269911 | AB23: 0.65395828 | AC23: -0.25654466 | AD23: 0.37828976 | AE23: 0.61960258 | AF23: -0.92492516 | AG23: -0.38879342 | AH23: 0.9798313 | AI23: -0.65517922 | AK23: 0 | AL23: =(AK23+D23)*C23 -> 0 | AM23: =100*(D23+AK23)/2 -> 0 | AO23: 0.2 | AP23: 0.2 | AQ23: =(D23+AK23)/2 -> 0 | AS23: 20 | AT23: {=ROUND(INDEX($D$4:$D$33,$AS23)*INDEX($AK$4:$AK$33,AT$3)*$AV$1,0)} -> 0 | AU23: {=ROUND(INDEX($D$4:$D$33,$AS23)*INDEX($AK$4:$AK$33,AU$3)*$AV$1,0)} -> 0 | AV23: {=ROUND(INDEX($D$4:$D$33,$AS23)*INDEX($AK$4:$AK$33,AV$3)*$AV$1,0)} -> 0 | AW23: {=ROUND(INDEX($D$4:$D$33,$AS23)*INDEX($AK$4:$AK$33,AW$3)*$AV$1,0)} -> 0 | AX23: {=ROUND(INDEX($D$4:$D$33,$AS23)*INDEX($AK$4:$AK$33,AX$3)*$AV$1,0)} -> 0 | AY23: {=ROUND(INDEX($D$4:$D$33,$AS23)*INDEX($AK$4:$AK$33,AY$3)*$AV$1,0)} -> 0 | AZ23: {=ROUND(INDEX($D$4:$D$33,$AS23)*INDEX($AK$4:$AK$33,AZ$3)*$AV$1,0)} -> 0 | BA23: {=ROUND(INDEX($D$4:$D$33,$AS23)*INDEX($AK$4:$AK$33,BA$3)*$AV$1,0)} -> 0 | ... BW23: {=ROUND(INDEX($D$4:$D$33,$AS23)*INDEX($AK$4:$AK$33,BW$3)*$AV$1,0)} -> 0 | BX23: =SUM(AT23:BW23) -> 0 | BZ23: =BX23+BM34 -> 0 | CA23: 20 | CD23: 0.72505215
B24: 21 | C24: 1.117955 | D24: 0.11370974 | F24: -0.48096576 | G24: -1.2483209 | H24: -0.68134527 | I24: -0.45653122 | J24: 0.31998546 | K24: 0.43451586 | L24: -0.55529142 | M24: 0.585609 | N24: 0.47193509 | O24: -0.088742526 | P24: -0.67262039 | Q24: 0.63076753 | R24: -0.091727009 | S24: -0.71664221 | T24: 0.17839386 | U24: 0.37023073 | V24: -1.0335282 | W24: 1.3197481 | X24: -1.5196093 | Y24: -1.1562869 | Z24: 0 | AA24: -0.54979683 | AB24: 0.15223389 | AC24: -0.61809277 | AD24: 0.040593509 | AE24: 0.57130574 | AF24: 0.45706178 | AG24: 0.066652412 | AH24: 0.86112585 | AI24: 0.79872485 | AK24: 0 | AL24: =(AK24+D24)*C24 -> 0.12712237 | AM24: =100*(D24+AK24)/2 -> 5.6854871 | AO24: 0.2 | AP24: 0.2 | AQ24: =(D24+AK24)/2 -> 0.056854871 | AS24: 21 | AT24: {=ROUND(INDEX($D$4:$D$33,$AS24)*INDEX($AK$4:$AK$33,AT$3)*$AV$1,0)} -> 0 | AU24: {=ROUND(INDEX($D$4:$D$33,$AS24)*INDEX($AK$4:$AK$33,AU$3)*$AV$1,0)} -> 0 | AV24: {=ROUND(INDEX($D$4:$D$33,$AS24)*INDEX($AK$4:$AK$33,AV$3)*$AV$1,0)} -> 0 | AW24: {=ROUND(INDEX($D$4:$D$33,$AS24)*INDEX($AK$4:$AK$33,AW$3)*$AV$1,0)} -> 0 | AX24: {=ROUND(INDEX($D$4:$D$33,$AS24)*INDEX($AK$4:$AK$33,AX$3)*$AV$1,0)} -> 0 | AY24: {=ROUND(INDEX($D$4:$D$33,$AS24)*INDEX($AK$4:$AK$33,AY$3)*$AV$1,0)} -> 0 | AZ24: {=ROUND(INDEX($D$4:$D$33,$AS24)*INDEX($AK$4:$AK$33,AZ$3)*$AV$1,0)} -> 0 | BA24: {=ROUND(INDEX($D$4:$D$33,$AS24)*INDEX($AK$4:$AK$33,BA$3)*$AV$1,0)} -> 0 | ... BW24: {=ROUND(INDEX($D$4:$D$33,$AS24)*INDEX($AK$4:$AK$33,BW$3)*$AV$1,0)} -> 114 | BX24: =SUM(AT24:BW24) -> 567 | BZ24: =BX24+BN34 -> 567 | CA24: 21 | CD24: -1.024855
B25: 22 | C25: -1.6495036 | D25: 0 | F25: -0.27486141 | G25: 0.7272653 | H25: -0.16950786 | I25: -0.31934552 | J25: -0.69244649 | K25: -0.80146826 | L25: 0.015641833 | M25: 0.7355604 | N25: 0.87079075 | O25: 0.39610667 | P25: -0.21852334 | Q25: -0.25993534 | R25: 0.25854183 | S25: 0.66286926 | T25: 0.68889433 | U25: -1.4983055 | V25: -0.032855534 | W25: -0.68361733 | X25: -0.33322338 | Y25: 1.2269911 | Z25: -0.54979683 | AA25: 0 | AB25: 0.25897737 | AC25: 0.65873636 | AD25: 0.75364654 | AE25: -1.1337283 | AF25: -0.98231525 | AG25: -0.02702548 | AH25: -1.0571606 | AI25: -0.3882918 | AK25: 0 | AL25: =(AK25+D25)*C25 -> 0 | AM25: =100*(D25+AK25)/2 -> 0 | AO25: 0.2 | AP25: 0.2 | AQ25: =(D25+AK25)/2 -> 0 | AS25: 22 | AT25: {=ROUND(INDEX($D$4:$D$33,$AS25)*INDEX($AK$4:$AK$33,AT$3)*$AV$1,0)} -> 0 | AU25: {=ROUND(INDEX($D$4:$D$33,$AS25)*INDEX($AK$4:$AK$33,AU$3)*$AV$1,0)} -> 0 | AV25: {=ROUND(INDEX($D$4:$D$33,$AS25)*INDEX($AK$4:$AK$33,AV$3)*$AV$1,0)} -> 0 | AW25: {=ROUND(INDEX($D$4:$D$33,$AS25)*INDEX($AK$4:$AK$33,AW$3)*$AV$1,0)} -> 0 | AX25: {=ROUND(INDEX($D$4:$D$33,$AS25)*INDEX($AK$4:$AK$33,AX$3)*$AV$1,0)} -> 0 | AY25: {=ROUND(INDEX($D$4:$D$33,$AS25)*INDEX($AK$4:$AK$33,AY$3)*$AV$1,0)} -> 0 | AZ25: {=ROUND(INDEX($D$4:$D$33,$AS25)*INDEX($AK$4:$AK$33,AZ$3)*$AV$1,0)} -> 0 | BA25: {=ROUND(INDEX($D$4:$D$33,$AS25)*INDEX($AK$4:$AK$33,BA$3)*$AV$1,0)} -> 0 | ... BW25: {=ROUND(INDEX($D$4:$D$33,$AS25)*INDEX($AK$4:$AK$33,BW$3)*$AV$1,0)} -> 0 | BX25: =SUM(AT25:BW25) -> 0 | BZ25: =BX25+BO34 -> 0 | CA25: 22 | CD25: 0.34726739
B26: 23 | C26: 0.67866722 | D26: 0.113072 | F26: 0.40771738 | G26: 0.24017396 | H26: -0.4757606 | I26: -0.37972602 | J26: -0.7355026 | K26: 0.70518651 | L26: -0.018422924 | M26: -0.46456859 | N26: 0.47923852 | O26: -0.36121428 | P26: 0.3153729 | Q26: 1.0724226 | R26: 0.66309382 | S26: -0.11325212 | T26: -0.080495707 | U26: 1.369755 | V26: -0.12077299 | W26: 0.21295831 | X26: 0.23050881 | Y26: 0.65395828 | Z26: 0.15223389 | AA26: 0.25897737 | AB26: 0 | AC26: 0.42429381 | AD26: 1.1460338 | AE26: -1.6702229 | AF26: -0.94800576 | AG26: 1.3314307 | AH26: 0.026363133 | AI26: 0.20062861 | AK26: 0 | AL26: =(AK26+D26)*C26 -> 0.076738261 | AM26: =100*(D26+AK26)/2 -> 5.6536001 | AO26: 0.2 | AP26: 0.2 | AQ26: =(D26+AK26)/2 -> 0.056536001 | AS26: 23 | AT26: {=ROUND(INDEX($D$4:$D$33,$AS26)*INDEX($AK$4:$AK$33,AT$3)*$AV$1,0)} -> 0 | AU26: {=ROUND(INDEX($D$4:$D$33,$AS26)*INDEX($AK$4:$AK$33,AU$3)*$AV$1,0)} -> 0 | AV26: {=ROUND(INDEX($D$4:$D$33,$AS26)*INDEX($AK$4:$AK$33,AV$3)*$AV$1,0)} -> 0 | AW26: {=ROUND(INDEX($D$4:$D$33,$AS26)*INDEX($AK$4:$AK$33,AW$3)*$AV$1,0)} -> 0 | AX26: {=ROUND(INDEX($D$4:$D$33,$AS26)*INDEX($AK$4:$AK$33,AX$3)*$AV$1,0)} -> 0 | AY26: {=ROUND(INDEX($D$4:$D$33,$AS26)*INDEX($AK$4:$AK$33,AY$3)*$AV$1,0)} -> 0 | AZ26: {=ROUND(INDEX($D$4:$D$33,$AS26)*INDEX($AK$4:$AK$33,AZ$3)*$AV$1,0)} -> 0 | BA26: {=ROUND(INDEX($D$4:$D$33,$AS26)*INDEX($AK$4:$AK$33,BA$3)*$AV$1,0)} -> 0 | ... BW26: {=ROUND(INDEX($D$4:$D$33,$AS26)*INDEX($AK$4:$AK$33,BW$3)*$AV$1,0)} -> 113 | BX26: =SUM(AT26:BW26) -> 565 | BZ26: =BX26+BP34 -> 565 | CA26: 23 | CD26: 0.93519631
B27: 24 | C27: 0.49432325 | D27: 0.068380584 | F27: -1.0795591 | G27: 1.4303774 | H27: 0.39053221 | I27: 1.287035 | J27: 0.24228624 | K27: 0.12696914 | L27: -0.72076685 | M27: 0.026586837 | N27: 0.096960817 | O27: -1.0755464 | P27: -0.013377367 | Q27: 0.11543283 | R27: -0.50993054 | S27: 0.29034042 | T27: -0.85745967 | U27: -0.40569876 | V27: 0.074523534 | W27: -0.42786752 | X27: 0.29825384 | Y27: -0.25654466 | Z27: -0.61809277 | AA27: 0.65873636 | AB27: 0.42429381 | AC27: 0 | AD27: 0.086163574 | AE27: -0.4961769 | AF27: 0.79823306 | AG27: 0.039216626 | AH27: 0.56771544 | AI27: 0.1504577 | AK27: 0.013099057 | AL27: =(AK27+D27)*C27 -> 0.040277281 | AM27: =100*(D27+AK27)/2 -> 4.0739821 | AO27: 0.2 | AP27: 0.2 | AQ27: =(D27+AK27)/2 -> 0.040739821 | AS27: 24 | AT27: {=ROUND(INDEX($D$4:$D$33,$AS27)*INDEX($AK$4:$AK$33,AT$3)*$AV$1,0)} -> 0 | AU27: {=ROUND(INDEX($D$4:$D$33,$AS27)*INDEX($AK$4:$AK$33,AU$3)*$AV$1,0)} -> 0 | AV27: {=ROUND(INDEX($D$4:$D$33,$AS27)*INDEX($AK$4:$AK$33,AV$3)*$AV$1,0)} -> 0 | AW27: {=ROUND(INDEX($D$4:$D$33,$AS27)*INDEX($AK$4:$AK$33,AW$3)*$AV$1,0)} -> 0 | AX27: {=ROUND(INDEX($D$4:$D$33,$AS27)*INDEX($AK$4:$AK$33,AX$3)*$AV$1,0)} -> 0 | AY27: {=ROUND(INDEX($D$4:$D$33,$AS27)*INDEX($AK$4:$AK$33,AY$3)*$AV$1,0)} -> 0 | AZ27: {=ROUND(INDEX($D$4:$D$33,$AS27)*INDEX($AK$4:$AK$33,AZ$3)*$AV$1,0)} -> 0 | BA27: {=ROUND(INDEX($D$4:$D$33,$AS27)*INDEX($AK$4:$AK$33,BA$3)*$AV$1,0)} -> 0 | ... BW27: {=ROUND(INDEX($D$4:$D$33,$AS27)*INDEX($AK$4:$AK$33,BW$3)*$AV$1,0)} -> 68 | BX27: =SUM(AT27:BW27) -> 341 | BZ27: =BX27+BQ34 -> 405 | CA27: 24 | CD27: -0.61847721
B28: 25 | C28: -0.58846858 | D28: 0 | F28: -0.39908677 | G28: 0.73773059 | H28: 0.59821356 | I28: -0.350397 | J28: -0.14624221 | K28: -0.11016452 | L28: -0.19473585 | M28: -1.727638 | N28: -0.30216288 | O28: 0.2185387 | P28: 1.7335255 | Q28: -1.0342342 | R28: -0.44939574 | S28: -0.27257047 | T28: -0.66629085 | U28: -0.47642953 | V28: -1.3606459 | W28: -0.079491271 | X28: -0.36664155 | Y28: 0.37828976 | Z28: 0.040593509 | AA28: 0.75364654 | AB28: 1.1460338 | AC28: 0.086163574 | AD28: 0 | AE28: 1.168072 | AF28: 0.0011993447 | AG28: -0.43408588 | AH28: 0.68861848 | AI28: -1.5575888 | AK28: 0 | AL28: =(AK28+D28)*C28 -> 0 | AM28: =100*(D28+AK28)/2 -> 0 | AO28: 0.2 | AP28: 0.2 | AQ28: =(D28+AK28)/2 -> 0 | AS28: 25 | AT28: {=ROUND(INDEX($D$4:$D$33,$AS28)*INDEX($AK$4:$AK$33,AT$3)*$AV$1,0)} -> 0 | AU28: {=ROUND(INDEX($D$4:$D$33,$AS28)*INDEX($AK$4:$AK$33,AU$3)*$AV$1,0)} -> 0 | AV28: {=ROUND(INDEX($D$4:$D$33,$AS28)*INDEX($AK$4:$AK$33,AV$3)*$AV$1,0)} -> 0 | AW28: {=ROUND(INDEX($D$4:$D$33,$AS28)*INDEX($AK$4:$AK$33,AW$3)*$AV$1,0)} -> 0 | AX28: {=ROUND(INDEX($D$4:$D$33,$AS28)*INDEX($AK$4:$AK$33,AX$3)*$AV$1,0)} -> 0 | AY28: {=ROUND(INDEX($D$4:$D$33,$AS28)*INDEX($AK$4:$AK$33,AY$3)*$AV$1,0)} -> 0 | AZ28: {=ROUND(INDEX($D$4:$D$33,$AS28)*INDEX($AK$4:$AK$33,AZ$3)*$AV$1,0)} -> 0 | BA28: {=ROUND(INDEX($D$4:$D$33,$AS28)*INDEX($AK$4:$AK$33,BA$3)*$AV$1,0)} -> 0 | ... BW28: {=ROUND(INDEX($D$4:$D$33,$AS28)*INDEX($AK$4:$AK$33,BW$3)*$AV$1,0)} -> 0 | BX28: =SUM(AT28:BW28) -> 0 | BZ28: =BX28+BR34 -> 0 | CA28: 25 | CD28: -0.62365581
B29: 26 | C29: -0.02392466 | D29: 0.088898427 | F29: -0.29849895 | G29: -1.1837138 | H29: -0.48622794 | I29: -0.72632977 | J29: -0.34829075 | K29: 0.24523051 | L29: 0.58644076 | M29: 0.11004884 | N29: 0.059194642 | O29: 0.26489408 | P29: 1.8760972 | Q29: 0.2352643 | R29: 0.099540007 | S29: 1.1156978 | T29: 0.063319815 | U29: -0.47587136 | V29: 0.65894818 | W29: -0.25306673 | X29: 0.14290745 | Y29: 0.61960258 | Z29: 0.57130574 | AA29: -1.1337283 | AB29: -1.6702229 | AC29: -0.4961769 | AD29: 1.168072 | AE29: 0 | AF29: 0.26847705 | AG29: 0.41508343 | AH29: 1.1036055 | AI29: 0.88464221 | AK29: 0 | AL29: =(AK29+D29)*C29 -> -0.0021268647 | AM29: =100*(D29+AK29)/2 -> 4.4449214 | AO29: 0.2 | AP29: 0.2 | AQ29: =(D29+AK29)/2 -> 0.044449214 | AS29: 26 | AT29: {=ROUND(INDEX($D$4:$D$33,$AS29)*INDEX($AK$4:$AK$33,AT$3)*$AV$1,0)} -> 0 | AU29: {=ROUND(INDEX($D$4:$D$33,$AS29)*INDEX($AK$4:$AK$33,AU$3)*$AV$1,0)} -> 0 | AV29: {=ROUND(INDEX($D$4:$D$33,$AS29)*INDEX($AK$4:$AK$33,AV$3)*$AV$1,0)} -> 0 | AW29: {=ROUND(INDEX($D$4:$D$33,$AS29)*INDEX($AK$4:$AK$33,AW$3)*$AV$1,0)} -> 0 | AX29: {=ROUND(INDEX($D$4:$D$33,$AS29)*INDEX($AK$4:$AK$33,AX$3)*$AV$1,0)} -> 0 | AY29: {=ROUND(INDEX($D$4:$D$33,$AS29)*INDEX($AK$4:$AK$33,AY$3)*$AV$1,0)} -> 0 | AZ29: {=ROUND(INDEX($D$4:$D$33,$AS29)*INDEX($AK$4:$AK$33,AZ$3)*$AV$1,0)} -> 0 | BA29: {=ROUND(INDEX($D$4:$D$33,$AS29)*INDEX($AK$4:$AK$33,BA$3)*$AV$1,0)} -> 0 | ... BW29: {=ROUND(INDEX($D$4:$D$33,$AS29)*INDEX($AK$4:$AK$33,BW$3)*$AV$1,0)} -> 89 | BX29: =SUM(AT29:BW29) -> 445 | BZ29: =BX29+BS34 -> 445 | CA29: 26 | CD29: 0.18182198
B30: 27 | C30: 2.191313 | D30: 0.2 | F30: -0.1230612 | G30: 0.013568088 | H30: -0.60813117 | I30: -0.016227706 | J30: -0.42590262 | K30: 0.61511345 | L30: -0.40362536 | M30: 0.92254772 | N30: -0.030154022 | O30: 0.63323588 | P30: 1.6156372 | Q30: 0.047254095 | R30: 1.0568343 | S30: -0.75834674 | T30: 1.2892994 | U30: -0.85448845 | V30: -0.046238841 | W30: -0.23110818 | X30: -0.81257225 | Y30: -0.92492516 | Z30: 0.45706178 | AA30: -0.98231525 | AB30: -0.94800576 | AC30: 0.79823306 | AD30: 0.0011993447 | AE30: 0.26847705 | AF30: 0 | AG30: -0.85327205 | AH30: 1.1216478 | AI30: 1.4316826 | AK30: 0.082915069 | AL30: =(AK30+D30)*C30 -> 0.61995547 | AM30: =100*(D30+AK30)/2 -> 14.145753 | AO30: 0.2 | AP30: 0.2 | AQ30: =(D30+AK30)/2 -> 0.14145753 | AS30: 27 | AT30: {=ROUND(INDEX($D$4:$D$33,$AS30)*INDEX($AK$4:$AK$33,AT$3)*$AV$1,0)} -> 0 | AU30: {=ROUND(INDEX($D$4:$D$33,$AS30)*INDEX($AK$4:$AK$33,AU$3)*$AV$1,0)} -> 0 | AV30: {=ROUND(INDEX($D$4:$D$33,$AS30)*INDEX($AK$4:$AK$33,AV$3)*$AV$1,0)} -> 0 | AW30: {=ROUND(INDEX($D$4:$D$33,$AS30)*INDEX($AK$4:$AK$33,AW$3)*$AV$1,0)} -> 0 | AX30: {=ROUND(INDEX($D$4:$D$33,$AS30)*INDEX($AK$4:$AK$33,AX$3)*$AV$1,0)} -> 0 | AY30: {=ROUND(INDEX($D$4:$D$33,$AS30)*INDEX($AK$4:$AK$33,AY$3)*$AV$1,0)} -> 0 | AZ30: {=ROUND(INDEX($D$4:$D$33,$AS30)*INDEX($AK$4:$AK$33,AZ$3)*$AV$1,0)} -> 0 | BA30: {=ROUND(INDEX($D$4:$D$33,$AS30)*INDEX($AK$4:$AK$33,BA$3)*$AV$1,0)} -> 0 | ... BW30: {=ROUND(INDEX($D$4:$D$33,$AS30)*INDEX($AK$4:$AK$33,BW$3)*$AV$1,0)} -> 200 | BX30: =SUM(AT30:BW30) -> 1000 | BZ30: =BX30+BT34 -> 1415 | CA30: 27 | CD30: -0.47583169
B31: 28 | C31: -1.400581 | D31: 0 | F31: -0.10603838 | G31: 0.58846491 | H31: 0.67040165 | I31: -1.3956432 | J31: -0.27710005 | K31: -0.4785071 | L31: -0.01132855 | M31: 0.36428359 | N31: 0.31454206 | O31: 0.80673694 | P31: 0.31655828 | Q31: 0.22304994 | R31: 0.66863418 | S31: 0.30311059 | T31: -0.93663854 | U31: 0.077655542 | V31: -1.1700651 | W31: 0.78536382 | X31: -1.4904833 | Y31: -0.38879342 | Z31: 0.066652412 | AA31: -0.02702548 | AB31: 1.3314307 | AC31: 0.039216626 | AD31: -0.43408588 | AE31: 0.41508343 | AF31: -0.85327205 | AG31: 0 | AH31: 0.60549397 | AI31: -0.027504131 | AK31: 0 | AL31: =(AK31+D31)*C31 -> 0 | AM31: =100*(D31+AK31)/2 -> 0 | AO31: 0.2 | AP31: 0.2 | AQ31: =(D31+AK31)/2 -> 0 | AS31: 28 | AT31: {=ROUND(INDEX($D$4:$D$33,$AS31)*INDEX($AK$4:$AK$33,AT$3)*$AV$1,0)} -> 0 | AU31: {=ROUND(INDEX($D$4:$D$33,$AS31)*INDEX($AK$4:$AK$33,AU$3)*$AV$1,0)} -> 0 | AV31: {=ROUND(INDEX($D$4:$D$33,$AS31)*INDEX($AK$4:$AK$33,AV$3)*$AV$1,0)} -> 0 | AW31: {=ROUND(INDEX($D$4:$D$33,$AS31)*INDEX($AK$4:$AK$33,AW$3)*$AV$1,0)} -> 0 | AX31: {=ROUND(INDEX($D$4:$D$33,$AS31)*INDEX($AK$4:$AK$33,AX$3)*$AV$1,0)} -> 0 | AY31: {=ROUND(INDEX($D$4:$D$33,$AS31)*INDEX($AK$4:$AK$33,AY$3)*$AV$1,0)} -> 0 | AZ31: {=ROUND(INDEX($D$4:$D$33,$AS31)*INDEX($AK$4:$AK$33,AZ$3)*$AV$1,0)} -> 0 | BA31: {=ROUND(INDEX($D$4:$D$33,$AS31)*INDEX($AK$4:$AK$33,BA$3)*$AV$1,0)} -> 0 | ... BW31: {=ROUND(INDEX($D$4:$D$33,$AS31)*INDEX($AK$4:$AK$33,BW$3)*$AV$1,0)} -> 0 | BX31: =SUM(AT31:BW31) -> 0 | BZ31: =BX31+BU34 -> 0 | CA31: 28 | CD31: -0.078833803
B32: 29 | C32: 0.48009949 | D32: 0 | F32: -1.3282765 | G32: -0.29981922 | H32: 0.54959304 | I32: -0.50482192 | J32: 1.1205095 | K32: -0.62813096 | L32: 1.5137951 | M32: -0.48944384 | N32: 0.070213828 | O32: 1.014683 | P32: 0.87214633 | Q32: -0.53573559 | R32: 0.52225361 | S32: -0.78797239 | T32: -1.2062316 | U32: 0.46751238 | V32: -1.2230416 | W32: -1.5118463 | X32: -0.042460111 | Y32: 0.9798313 | Z32: 0.86112585 | AA32: -1.0571606 | AB32: 0.026363133 | AC32: 0.56771544 | AD32: 0.68861848 | AE32: 1.1036055 | AF32: 1.1216478 | AG32: 0.60549397 | AH32: 0 | AI32: 0.70610525 | AK32: 0.14132567 | AL32: =(AK32+D32)*C32 -> 0.067850382 | AM32: =100*(D32+AK32)/2 -> 7.0662835 | AO32: 0.2 | AP32: 0.2 | AQ32: =(D32+AK32)/2 -> 0.070662835 | AS32: 29 | AT32: {=ROUND(INDEX($D$4:$D$33,$AS32)*INDEX($AK$4:$AK$33,AT$3)*$AV$1,0)} -> 0 | AU32: {=ROUND(INDEX($D$4:$D$33,$AS32)*INDEX($AK$4:$AK$33,AU$3)*$AV$1,0)} -> 0 | AV32: {=ROUND(INDEX($D$4:$D$33,$AS32)*INDEX($AK$4:$AK$33,AV$3)*$AV$1,0)} -> 0 | AW32: {=ROUND(INDEX($D$4:$D$33,$AS32)*INDEX($AK$4:$AK$33,AW$3)*$AV$1,0)} -> 0 | AX32: {=ROUND(INDEX($D$4:$D$33,$AS32)*INDEX($AK$4:$AK$33,AX$3)*$AV$1,0)} -> 0 | AY32: {=ROUND(INDEX($D$4:$D$33,$AS32)*INDEX($AK$4:$AK$33,AY$3)*$AV$1,0)} -> 0 | AZ32: {=ROUND(INDEX($D$4:$D$33,$AS32)*INDEX($AK$4:$AK$33,AZ$3)*$AV$1,0)} -> 0 | BA32: {=ROUND(INDEX($D$4:$D$33,$AS32)*INDEX($AK$4:$AK$33,BA$3)*$AV$1,0)} -> 0 | ... BW32: {=ROUND(INDEX($D$4:$D$33,$AS32)*INDEX($AK$4:$AK$33,BW$3)*$AV$1,0)} -> 0 | BX32: =SUM(AT32:BW32) -> 0 | BZ32: =BX32+BV34 -> 705 | CA32: 29 | CD32: 0.67748319
B33: 30 | C33: 0.20755068 | D33: 0.2 | F33: 1.231834 | G33: -1.4152708 | H33: 0.59078559 | I33: -0.24240916 | J33: -0.33797024 | K33: -0.62868964 | L33: 0.8933793 | M33: 0.27096414 | N33: -0.084051916 | O33: 0.2950383 | P33: 0.71645601 | Q33: -0.61484171 | R33: -0.56192395 | S33: 0.48684463 | T33: 1.1212401 | U33: 0.88400994 | V33: -0.081744024 | W33: -0.94170341 | X33: -1.6566137 | Y33: -0.65517922 | Z33: 0.79872485 | AA33: -0.3882918 | AB33: 0.20062861 | AC33: 0.1504577 | AD33: -1.5575888 | AE33: 0.88464221 | AF33: 1.4316826 | AG33: -0.027504131 | AH33: 0.70610525 | AI33: 0 | AK33: 0.2 | AL33: =(AK33+D33)*C33 -> 0.083020271 | AM33: =100*(D33+AK33)/2 -> 20 | AO33: 0.2 | AP33: 0.2 | AQ33: =(D33+AK33)/2 -> 0.2 | AS33: 30 | AT33: {=ROUND(INDEX($D$4:$D$33,$AS33)*INDEX($AK$4:$AK$33,AT$3)*$AV$1,0)} -> 0 | AU33: {=ROUND(INDEX($D$4:$D$33,$AS33)*INDEX($AK$4:$AK$33,AU$3)*$AV$1,0)} -> 0 | AV33: {=ROUND(INDEX($D$4:$D$33,$AS33)*INDEX($AK$4:$AK$33,AV$3)*$AV$1,0)} -> 0 | AW33: {=ROUND(INDEX($D$4:$D$33,$AS33)*INDEX($AK$4:$AK$33,AW$3)*$AV$1,0)} -> 0 | AX33: {=ROUND(INDEX($D$4:$D$33,$AS33)*INDEX($AK$4:$AK$33,AX$3)*$AV$1,0)} -> 0 | AY33: {=ROUND(INDEX($D$4:$D$33,$AS33)*INDEX($AK$4:$AK$33,AY$3)*$AV$1,0)} -> 0 | AZ33: {=ROUND(INDEX($D$4:$D$33,$AS33)*INDEX($AK$4:$AK$33,AZ$3)*$AV$1,0)} -> 0 | BA33: {=ROUND(INDEX($D$4:$D$33,$AS33)*INDEX($AK$4:$AK$33,BA$3)*$AV$1,0)} -> 0 | ... BW33: {=ROUND(INDEX($D$4:$D$33,$AS33)*INDEX($AK$4:$AK$33,BW$3)*$AV$1,0)} -> 200 | BX33: =SUM(AT33:BW33) -> 1000 | BZ33: =BX33+BW34 -> 2000 | CA33: 30 | CD33: 0.016397195
D34: =SUM(D4:D33) -> 1 | AK34: =SUM(AK4:AK33) -> 1 | AL34: GCA | AM34: SCA | AQ34: =SUM(AQ4:AQ33) -> 1 | AT34: =SUM(AT4:AT33) -> 0 | AU34: =SUM(AU4:AU33) -> 0 | AV34: =SUM(AV4:AV33) -> 0 | AW34: =SUM(AW4:AW33) -> 0 | AX34: =SUM(AX4:AX33) -> 0 | AY34: =SUM(AY4:AY33) -> 0 | AZ34: =SUM(AZ4:AZ33) -> 0 | BA34: =SUM(BA4:BA33) -> 0 | ... BW34: =SUM(BW4:BW33) -> 1000
AK35: Gain | AL35: =0.5*SUM(AL4:AL33) -> 0.74844369 | AM35: =SUM(F42:AI71) -> 0.56014742 | AT35: =SUM(AT4:BW33) -> 4998
AK37: input NS = | AL37: 5 | AN37: Total Gain = | AO37: =AL35+AM35 -> 1.3085911
AK38: Final NS | AL38: =AT110 -> 5 | AN38: SCA/Total = | AO38: =AM35/AO37 -> 0.42805382
F41: 1 | G41: 2 | H41: 3 | I41: 4 | J41: 5 | K41: 6 | L41: 7 | M41: 8 | N41: 9 | O41: 10 | P41: 11 | Q41: 12 | R41: 13 | S41: 14 | T41: 15 | U41: 16 | V41: 17 | W41: 18 | X41: 19 | Y41: 20 | Z41: 21 | AA41: 22 | AB41: 23 | AC41: 24 | AD41: 25 | AE41: 26 | AF41: 27 | AG41: 28 | AH41: 29 | AI41: 30
E42: 1 | F42: {=INDEX($D$4:$D$33,$E42)*INDEX($AK$4:$AK$33,F$41)*F4} -> 0 | G42: {=INDEX($D$4:$D$33,$E42)*INDEX($AK$4:$AK$33,G$41)*G4} -> 0 | H42: {=INDEX($D$4:$D$33,$E42)*INDEX($AK$4:$AK$33,H$41)*H4} -> 0 | I42: {=INDEX($D$4:$D$33,$E42)*INDEX($AK$4:$AK$33,I$41)*I4} -> 0 | J42: {=INDEX($D$4:$D$33,$E42)*INDEX($AK$4:$AK$33,J$41)*J4} -> 0 | K42: {=INDEX($D$4:$D$33,$E42)*INDEX($AK$4:$AK$33,K$41)*K4} -> 0 | L42: {=INDEX($D$4:$D$33,$E42)*INDEX($AK$4:$AK$33,L$41)*L4} -> 0 | M42: {=INDEX($D$4:$D$33,$E42)*INDEX($AK$4:$AK$33,M$41)*M4} -> 0 | ... AI42: {=INDEX($D$4:$D$33,$E42)*INDEX($AK$4:$AK$33,AI$41)*AI4} -> 0 | AR42: G matrix | AT42: 1 | AU42: 2 | AV42: 3 | AW42: 4 | AX42: 5 | AY42: 6 | AZ42: 7 | BA42: 8 | BB42: 9 | BC42: 10 | BD42: 11 | BE42: 12 | BF42: 13 | BG42: 14 | BH42: 15 | BI42: 16 | BJ42: 17 | BK42: 18 | BL42: 19 | BM42: 20 | BN42: 21 | BO42: 22 | BP42: 23 | BQ42: 24 | BR42: 25 | BS42: 26 | BT42: 27 | BU42: 28 | BV42: 29 | BW42: 30
E43: 2 | F43: {=INDEX($D$4:$D$33,$E43)*INDEX($AK$4:$AK$33,F$41)*F5} -> 0 | G43: {=INDEX($D$4:$D$33,$E43)*INDEX($AK$4:$AK$33,G$41)*G5} -> 0 | H43: {=INDEX($D$4:$D$33,$E43)*INDEX($AK$4:$AK$33,H$41)*H5} -> 0 | I43: {=INDEX($D$4:$D$33,$E43)*INDEX($AK$4:$AK$33,I$41)*I5} -> 0 | J43: {=INDEX($D$4:$D$33,$E43)*INDEX($AK$4:$AK$33,J$41)*J5} -> 0 | K43: {=INDEX($D$4:$D$33,$E43)*INDEX($AK$4:$AK$33,K$41)*K5} -> 0 | L43: {=INDEX($D$4:$D$33,$E43)*INDEX($AK$4:$AK$33,L$41)*L5} -> 0 | M43: {=INDEX($D$4:$D$33,$E43)*INDEX($AK$4:$AK$33,M$41)*M5} -> 0 | ... AI43: {=INDEX($D$4:$D$33,$E43)*INDEX($AK$4:$AK$33,AI$41)*AI5} -> 0 | AS43: 1 | AT43: 1.0629447 | AU43: 0 | AV43: 0 | AW43: 0.25858527 | AX43: 0 | AY43: 0 | AZ43: 0.24699968 | BA43: 0.25681435 | BB43: 0.24151709 | BC43: 0 | BD43: 0 | BE43: 0.25094431 | BF43: 0 | BG43: 0 | BH43: 0 | BI43: 0 | BJ43: 0 | BK43: 0 | BL43: 0 | BM43: 0 | BN43: 0.25781807 | BO43: 0 | BP43: 0 | BQ43: 0 | BR43: 0 | BS43: 0 | BT43: 0 | BU43: 0 | BV43: 0 | BW43: 0.24324365
...

Sheet SCA_flatten
A1: 1 | B1: {=INDEX(Optimization!$F$4:$AI$33, INT((ROW()-1)/COLUMNS(Optimization!$F$4:$AI$33))+1, MOD(ROW()-1, COLUMNS(Optimization!$F$4:$AI$33))+1)} -> 0 | C1: {=INDEX(Optimization!$AT$4:$BW$33, INT((ROW()-1)/COLUMNS(Optimization!$AT$4:$BW$33))+1, MOD(ROW()-1, COLUMNS(Optimization!$AT$4:$BW$33))+1)} -> 0 | E1: Cross-specific contribution
A2: 2 | B2: {=INDEX(Optimization!$F$4:$AI$33, INT((ROW()-1)/COLUMNS(Optimization!$F$4:$AI$33))+1, MOD(ROW()-1, COLUMNS(Optimization!$F$4:$AI$33))+1)} -> 1.63653 | C2: {=INDEX(Optimization!$AT$4:$BW$33, INT((ROW()-1)/COLUMNS(Optimization!$AT$4:$BW$33))+1, MOD(ROW()-1, COLUMNS(Optimization!$AT$4:$BW$33))+1)} -> 0
A3: 3 | B3: {=INDEX(Optimization!$F$4:$AI$33, INT((ROW()-1)/COLUMNS(Optimization!$F$4:$AI$33))+1, MOD(ROW()-1, COLUMNS(Optimization!$F$4:$AI$33))+1)} -> 0.14443892 | C3: {=INDEX(Optimization!$AT$4:$BW$33, INT((ROW()-1)/COLUMNS(Optimization!$AT$4:$BW$33))+1, MOD(ROW()-1, COLUMNS(Optimization!$AT$4:$BW$33))+1)} -> 0 | N3: 0 | O3: 0
A4: 4 | B4: {=INDEX(Optimization!$F$4:$AI$33, INT((ROW()-1)/COLUMNS(Optimization!$F$4:$AI$33))+1, MOD(ROW()-1, COLUMNS(Optimization!$F$4:$AI$33))+1)} -> -0.13035389 | C4: {=INDEX(Optimization!$AT$4:$BW$33, INT((ROW()-1)/COLUMNS(Optimization!$AT$4:$BW$33))+1, MOD(ROW()-1, COLUMNS(Optimization!$AT$4:$BW$33))+1)} -> 0 | N4: 0 | O4: 120
A5: 5 | B5: {=INDEX(Optimization!$F$4:$AI$33, INT((ROW()-1)/COLUMNS(Optimization!$F$4:$AI$33))+1, MOD(ROW()-1, COLUMNS(Optimization!$F$4:$AI$33))+1)} -> 0.65183594 | C5: {=INDEX(Optimization!$AT$4:$BW$33, INT((ROW()-1)/COLUMNS(Optimization!$AT$4:$BW$33))+1, MOD(ROW()-1, COLUMNS(Optimization!$AT$4:$BW$33))+1)} -> 0
A6: 6 | B6: {=INDEX(Optimization!$F$4:$AI$33, INT((ROW()-1)/COLUMNS(Optimization!$F$4:$AI$33))+1, MOD(ROW()-1, COLUMNS(Optimization!$F$4:$AI$33))+1)} -> 0.10715813 | C6: {=INDEX(Optimization!$AT$4:$BW$33, INT((ROW()-1)/COLUMNS(Optimization!$AT$4:$BW$33))+1, MOD(ROW()-1, COLUMNS(Optimization!$AT$4:$BW$33))+1)} -> 0
A7: 7 | B7: {=INDEX(Optimization!$F$4:$AI$33, INT((ROW()-1)/COLUMNS(Optimization!$F$4:$AI$33))+1, MOD(ROW()-1, COLUMNS(Optimization!$F$4:$AI$33))+1)} -> -1.4849538 | C7: {=INDEX(Optimization!$AT$4:$BW$33, INT((ROW()-1)/COLUMNS(Optimization!$AT$4:$BW$33))+1, MOD(ROW()-1, COLUMNS(Optimization!$AT$4:$BW$33))+1)} -> 0
A8: 8 | B8: {=INDEX(Optimization!$F$4:$AI$33, INT((ROW()-1)/COLUMNS(Optimization!$F$4:$AI$33))+1, MOD(ROW()-1, COLUMNS(Optimization!$F$4:$AI$33))+1)} -> -0.055826057 | C8: {=INDEX(Optimization!$AT$4:$BW$33, INT((ROW()-1)/COLUMNS(Optimization!$AT$4:$BW$33))+1, MOD(ROW()-1, COLUMNS(Optimization!$AT$4:$BW$33))+1)} -> 0
A9: 9 | B9: {=INDEX(Optimization!$F$4:$AI$33, INT((ROW()-1)/COLUMNS(Optimization!$F$4:$AI$33))+1, MOD(ROW()-1, COLUMNS(Optimization!$F$4:$AI$33))+1)} -> 0.23310062 | C9: {=INDEX(Optimization!$AT$4:$BW$33, INT((ROW()-1)/COLUMNS(Optimization!$AT$4:$BW$33))+1, MOD(ROW()-1, COLUMNS(Optimization!$AT$4:$BW$33))+1)} -> 0
A10: 10 | B10: {=INDEX(Optimization!$F$4:$AI$33, INT((ROW()-1)/COLUMNS(Optimization!$F$4:$AI$33))+1, MOD(ROW()-1, COLUMNS(Optimization!$F$4:$AI$33))+1)} -> -0.55120302 | C10: {=INDEX(Optimization!$AT$4:$BW$33, INT((ROW()-1)/COLUMNS(Optimization!$AT$4:$BW$33))+1, MOD(ROW()-1, COLUMNS(Optimization!$AT$4:$BW$33))+1)} -> 0
A11: 11 | B11: {=INDEX(Optimization!$F$4:$AI$33, INT((ROW()-1)/COLUMNS(Optimization!$F$4:$AI$33))+1, MOD(ROW()-1, COLUMNS(Optimization!$F$4:$AI$33))+1)} -> -0.0083762498 | C11: {=INDEX(Optimization!$AT$4:$BW$33, INT((ROW()-1)/COLUMNS(Optimization!$AT$4:$BW$33))+1, MOD(ROW()-1, COLUMNS(Optimization!$AT$4:$BW$33))+1)} -> 0
A12: 12 | B12: {=INDEX(Optimization!$F$4:$AI$33, INT((ROW()-1)/COLUMNS(Optimization!$F$4:$AI$33))+1, MOD(ROW()-1, COLUMNS(Optimization!$F$4:$AI$33))+1)} -> -1.5917527 | C12: {=INDEX(Optimization!$AT$4:$BW$33, INT((ROW()-1)/COLUMNS(Optimization!$AT$4:$BW$33))+1, MOD(ROW()-1, COLUMNS(Optimization!$AT$4:$BW$33))+1)} -> 0
A13: 13 | B13: {=INDEX(Optimization!$F$4:$AI$33, INT((ROW()-1)/COLUMNS(Optimization!$F$4:$AI$33))+1, MOD(ROW()-1, COLUMNS(Optimization!$F$4:$AI$33))+1)} -> 0.48265321 | C13: {=INDEX(Optimization!$AT$4:$BW$33, INT((ROW()-1)/COLUMNS(Optimization!$AT$4:$BW$33))+1, MOD(ROW()-1, COLUMNS(Optimization!$AT$4:$BW$33))+1)} -> 0
A14: 14 | B14: {=INDEX(Optimization!$F$4:$AI$33, INT((ROW()-1)/COLUMNS(Optimization!$F$4:$AI$33))+1, MOD(ROW()-1, COLUMNS(Optimization!$F$4:$AI$33))+1)} -> 0.42670492 | C14: {=INDEX(Optimization!$AT$4:$BW$33, INT((ROW()-1)/COLUMNS(Optimization!$AT$4:$BW$33))+1, MOD(ROW()-1, COLUMNS(Optimization!$AT$4:$BW$33))+1)} -> 0
A15: 15 | B15: {=INDEX(Optimization!$F$4:$AI$33, INT((ROW()-1)/COLUMNS(Optimization!$F$4:$AI$33))+1, MOD(ROW()-1, COLUMNS(Optimization!$F$4:$AI$33))+1)} -> 0.21735479 | C15: {=INDEX(Optimization!$AT$4:$BW$33, INT((ROW()-1)/COLUMNS(Optimization!$AT$4:$BW$33))+1, MOD(ROW()-1, COLUMNS(Optimization!$AT$4:$BW$33))+1)} -> 0
A16: 16 | B16: {=INDEX(Optimization!$F$4:$AI$33, INT((ROW()-1)/COLUMNS(Optimization!$F$4:$AI$33))+1, MOD(ROW()-1, COLUMNS(Optimization!$F$4:$AI$33))+1)} -> -0.74091372 | C16: {=INDEX(Optimization!$AT$4:$BW$33, INT((ROW()-1)/COLUMNS(Optimization!$AT$4:$BW$33))+1, MOD(ROW()-1, COLUMNS(Optimization!$AT$4:$BW$33))+1)} -> 0
... A1024: 1024 | B1024: {=INDEX(Optimization!$F$4:$AI$33, INT((ROW()-1)/COLUMNS(Optimization!$F$4:$AI$33))+1, MOD(ROW()-1, COLUMNS(Optimization!$F$4:$AI$33))+1)} -> #REF! | C1024: {=INDEX(Optimization!$AT$4:$BW$33, INT((ROW()-1)/COLUMNS(Optimization!$AT$4:$BW$33))+1, MOD(ROW()-1, COLUMNS(Optimization!$AT$4:$BW$33))+1)} -> #REF!
